Workbook

Sheet SQL Practice Links
A1: # | B1: Section | C1: Topic | D1: Key Concepts | E1: Q1 (easiest) | F1: Q2 | G1: Q3 | H1: Q4 | I1: Q5 (hardest)
A2: 1 | B2: SQL Basics | C2: SELECT & Column Aliases | D2: SELECT *, choosing columns, AS aliases | E2: =HYPERLINK("https://www.hackerrank.com/challenges/select-all-sql/problem","Select All"&CHAR(10)&"HackerRank · Easy") -> Select All HackerRank · Easy | F2: =HYPERLINK("https://www.hackerrank.com/challenges/weather-observation-station-1/problem","Weather Observation Station 1"&CHAR(10)&"HackerRank · Easy") -> Weather Observation Station 1 HackerRank · Easy | G2: =HYPERLINK("https://www.codechef.com/practice/course/sql-case-studies-topic-wise/SQLBP01/problems/SQLPBP11","All Products (SQLPBP11)"&CHAR(10)&"CodeChef · Easy") -> All Products (SQLPBP11) CodeChef · Easy | H2: =HYPERLINK("https://www.codechef.com/learn/course/sql/SQ00LS04/problems/GSQ17","SELECT Query (GSQ17)"&CHAR(10)&"CodeChef · Easy") -> SELECT Query (GSQ17) CodeChef · Easy | I2: =HYPERLINK("https://www.codechef.com/learn/course/sql/SQ00LS08/problems/GSQ37A","Rename columns using As (GSQ37A)"&CHAR(10)&"CodeChef · Easy") -> Rename columns using As (GSQ37A) CodeChef · Easy
A3: 2 | C3: CREATE TABLE & INSERT INTO | D3: Column data types, CREATE TABLE, single- and multi-row INSERT | E3: =HYPERLINK("https://www.codechef.com/learn/course/sql/SQ00LS01/problems/GSQ04","Create table (GSQ04)"&CHAR(10)&"CodeChef · Easy") -> Create table (GSQ04) CodeChef · Easy | F3: =HYPERLINK("https://www.codechef.com/learn/course/sql/SQ00LS01/problems/GSQ07","How to insert to a table (GSQ07)"&CHAR(10)&"CodeChef · Easy") -> How to insert to a table (GSQ07) CodeChef · Easy | G3: =HYPERLINK("https://www.codechef.com/learn/course/sql/SQ00LS01/problems/GSQ05","Inserting Data into a Table (GSQ05)"&CHAR(10)&"CodeChef · Easy") -> Inserting Data into a Table (GSQ05) CodeChef · Easy | H3: =HYPERLINK("https://www.codechef.com/learn/course/sql/SQ00LS01/problems/GSQ06","Debug this query (GSQ06)"&CHAR(10)&"CodeChef · Medium") -> Debug this query (GSQ06) CodeChef · Medium | I3: =HYPERLINK("https://www.codechef.com/learn/course/sql/SQ00LS03/problems/GSQ53","Project - Customer Database (GSQ53)"&CHAR(10)&"CodeChef · Medium") -> Project - Customer Database (GSQ53) CodeChef · Medium
A4: 3 | C4: Filtering with WHERE | D4: Comparison operators, AND / OR / NOT, IS NULL / IS NOT NULL | E4: =HYPERLINK("https://leetcode.com/problems/recyclable-and-low-fat-products/","1757. Recyclable and Low Fat Products"&CHAR(10)&"LeetCode · Easy") -> 1757. Recyclable and Low Fat Products LeetCode · Easy | F4: =HYPERLINK("https://www.hackerrank.com/challenges/revising-the-select-query/problem","Revising the Select Query I"&CHAR(10)&"HackerRank · Easy") -> Revising the Select Query I HackerRank · Easy | G4: =HYPERLINK("https://www.codechef.com/practice/course/sql-case-studies-topic-wise/SQLBP01/problems/SQLPBP12","High Price of Products (SQLPBP12)"&CHAR(10)&"CodeChef · Easy") -> High Price of Products (SQLPBP12) CodeChef · Easy | H4: =HYPERLINK("https://www.codechef.com/practice/course/sql-case-studies-topic-wise/SQLBP01/problems/SQLPBP07","Handling NULL Values (SQLPBP07)"&CHAR(10)&"CodeChef · Easy") -> Handling NULL Values (SQLPBP07) CodeChef · Easy | I4: =HYPERLINK("https://leetcode.com/problems/find-customer-referee/","584. Find Customer Referee"&CHAR(10)&"LeetCode · Medium") -> 584. Find Customer Referee LeetCode · Medium
A5: 4 | C5: DISTINCT, ORDER BY & LIMIT | D5: Removing duplicates, sorting (ASC / DESC, several keys), top-N with LIMIT | E5: =HYPERLINK("https://www.codechef.com/practice/course/sql-case-studies-topic-wise/SQLBP01/problems/SQLPBP13","Distinct Companies (SQLPBP13)"&CHAR(10)&"CodeChef · Easy") -> Distinct Companies (SQLPBP13) CodeChef · Easy | F5: =HYPERLINK("https://www.hackerrank.com/challenges/name-of-employees/problem","Employee Names"&CHAR(10)&"HackerRank · Easy") -> Employee Names HackerRank · Easy | G5: =HYPERLINK("https://leetcode.com/problems/article-views-i/","1148. Article Views I"&CHAR(10)&"LeetCode · Easy") -> 1148. Article Views I LeetCode · Easy | H5: =HYPERLINK("https://www.hackerrank.com/challenges/salary-of-employees/problem","Employee Salaries"&CHAR(10)&"HackerRank · Medium") -> Employee Salaries HackerRank · Medium | I5: =HYPERLINK("https://www.codechef.com/learn/course/sql/BEGSQLPR/problems/RSMSPR03C","Task-3C Data Retrieval Using Queries (RSMSPR03C)"&CHAR(10)&"CodeChef · Medium") -> Task-3C Data Retrieval Using Queries (RSMSPR03C) CodeChef · Medium
A6: 5 | C6: BETWEEN, IN & LIKE | D6: Ranges, value lists, wildcard patterns (% and _), NOT LIKE | E6: =HYPERLINK("https://www.codechef.com/learn/course/sql/SQ00LS04/problems/GSQ19A","BETWEEN (GSQ19A)"&CHAR(10)&"CodeChef · Easy") -> BETWEEN (GSQ19A) CodeChef · Easy | F6: =HYPERLINK("https://www.codechef.com/learn/course/sql/SQ00LS05/problems/GSQ26","Practice - Filter with multiple Like patterns (GSQ26)"&CHAR(10)&"CodeChef · Easy") -> Practice - Filter with multiple Like patterns (GSQ26) CodeChef · Easy | G6: =HYPERLINK("https://leetcode.com/problems/patients-with-a-condition/","1527. Patients With a Condition"&CHAR(10)&"LeetCode · Medium") -> 1527. Patients With a Condition LeetCode · Medium | H6: =HYPERLINK("https://www.hackerrank.com/challenges/weather-observation-station-6/problem","Weather Observation Station 6"&CHAR(10)&"HackerRank · Medium") -> Weather Observation Station 6 HackerRank · Medium | I6: =HYPERLINK("https://www.hackerrank.com/challenges/weather-observation-station-12/problem","Weather Observation Station 12"&CHAR(10)&"HackerRank · Challenging") -> Weather Observation Station 12 HackerRank · Challenging
A7: 6 | B7: Functions & Aggregation | C7: String Functions | D7: LENGTH, UPPER / LOWER, SUBSTRING / LEFT / RIGHT, CONCAT, REPLACE, REGEXP | E7: =HYPERLINK("https://leetcode.com/problems/invalid-tweets/","1683. Invalid Tweets"&CHAR(10)&"LeetCode · Easy") -> 1683. Invalid Tweets LeetCode · Easy | F7: =HYPERLINK("https://www.hackerrank.com/challenges/more-than-75-marks/problem","Higher Than 75 Marks"&CHAR(10)&"HackerRank · Easy") -> Higher Than 75 Marks HackerRank · Easy | G7: =HYPERLINK("https://leetcode.com/problems/fix-names-in-a-table/","1667. Fix Names in a Table"&CHAR(10)&"LeetCode · Medium") -> 1667. Fix Names in a Table LeetCode · Medium | H7: =HYPERLINK("https://www.hackerrank.com/challenges/weather-observation-station-5/problem","Weather Observation Station 5"&CHAR(10)&"HackerRank · Medium") -> Weather Observation Station 5 HackerRank · Medium | I7: =HYPERLINK("https://leetcode.com/problems/find-users-with-valid-e-mails/","1517. Find Users With Valid E-Mails"&CHAR(10)&"LeetCode · Challenging") -> 1517. Find Users With Valid E-Mails LeetCode · Challenging
A8: 7 | C8: Aggregate Functions | D8: COUNT, SUM, AVG, MIN, MAX (with WHERE) | E8: =HYPERLINK("https://www.hackerrank.com/challenges/revising-aggregations-the-count-function/problem","Revising Aggregations - The Count Function"&CHAR(10)&"HackerRank · Easy") -> Revising Aggregations - The Count Function HackerRank · Easy | F8: =HYPERLINK("https://www.codechef.com/practice/course/sql-case-studies-topic-wise/SQLBP01/problems/SQLPBP02","Fiction Collection Size (SQLPBP02)"&CHAR(10)&"CodeChef · Easy") -> Fiction Collection Size (SQLPBP02) CodeChef · Easy | G8: =HYPERLINK("https://www.codechef.com/practice/course/sql-case-studies-topic-wise/SQLBP01/problems/SQLPBP14","Average Salary (SQLPBP14)"&CHAR(10)&"CodeChef · Easy") -> Average Salary (SQLPBP14) CodeChef · Easy | H8: =HYPERLINK("https://www.codechef.com/learn/course/sql/SQ00LS09/problems/GSQ44","Problem - SUM() and AVG() (GSQ44)"&CHAR(10)&"CodeChef · Medium") -> Problem - SUM() and AVG() (GSQ44) CodeChef · Medium | I8: =HYPERLINK("https://www.hackerrank.com/challenges/population-density-difference/problem","Population Density Difference"&CHAR(10)&"HackerRank · Medium") -> Population Density Difference HackerRank · Medium
A9: 8 | C9: Numeric Functions | D9: ROUND, CEIL / FLOOR, MOD, POWER / SQRT | E9: =HYPERLINK("https://www.hackerrank.com/challenges/weather-observation-station-3/problem","Weather Observation Station 3"&CHAR(10)&"HackerRank · Easy") -> Weather Observation Station 3 HackerRank · Easy | F9: =HYPERLINK("https://leetcode.com/problems/not-boring-movies/","620. Not Boring Movies"&CHAR(10)&"LeetCode · Easy") -> 620. Not Boring Movies LeetCode · Easy | G9: =HYPERLINK("https://www.codechef.com/learn/course/sql/SQ00LS08/problems/GSQ41","Problem-ROUND() (GSQ41)"&CHAR(10)&"CodeChef · Easy") -> Problem-ROUND() (GSQ41) CodeChef · Easy | H9: =HYPERLINK("https://www.hackerrank.com/challenges/the-blunder/problem","The Blunder"&CHAR(10)&"HackerRank · Medium") -> The Blunder HackerRank · Medium | I9: =HYPERLINK("https://www.hackerrank.com/challenges/weather-observation-station-19/problem","Weather Observation Station 19"&CHAR(10)&"HackerRank · Challenging") -> Weather Observation Station 19 HackerRank · Challenging
A10: 9 | C10: GROUP BY | D10: Grouping by one or more columns, COUNT(DISTINCT), GROUP_CONCAT / STRING_AGG | E10: =HYPERLINK("https://leetcode.com/problems/number-of-unique-subjects-taught-by-each-teacher/","2356. Number of Unique Subjects Taught by Each Teacher"&CHAR(10)&"LeetCode · Easy") -> 2356. Number of Unique Subjects Taught by Each Teacher LeetCode · Easy | F10: =HYPERLINK("https://www.codechef.com/practice/course/sql-case-studies-topic-wise/SQLBP01/problems/SQLPBP09","Department of Each Employee (SQLPBP09)"&CHAR(10)&"CodeChef · Easy") -> Department of Each Employee (SQLPBP09) CodeChef · Easy | G10: =HYPERLINK("https://leetcode.com/problems/find-total-time-spent-by-each-employee/","1741. Find Total Time Spent by Each Employee"&CHAR(10)&"LeetCode · Easy") -> 1741. Find Total Time Spent by Each Employee LeetCode · Easy | H10: =HYPERLINK("https://leetcode.com/problems/group-sold-products-by-the-date/","1484. Group Sold Products By The Date"&CHAR(10)&"LeetCode · Medium") -> 1484. Group Sold Products By The Date LeetCode · Medium | I10: =HYPERLINK("https://www.hackerrank.com/challenges/the-pads/problem","The PADS"&CHAR(10)&"HackerRank · Challenging") -> The PADS HackerRank · Challenging
A11: 10 | C11: HAVING | D11: Filtering groups, WHERE vs HAVING | E11: =HYPERLINK("https://leetcode.com/problems/duplicate-emails/","182. Duplicate Emails"&CHAR(10)&"LeetCode · Easy") -> 182. Duplicate Emails LeetCode · Easy | F11: =HYPERLINK("https://leetcode.com/problems/classes-with-at-least-5-students/","596. Classes With at Least 5 Students"&CHAR(10)&"LeetCode · Easy") -> 596. Classes With at Least 5 Students LeetCode · Easy | G11: =HYPERLINK("https://www.codechef.com/learn/course/sql/SQ00LS09/problems/GSQ46","Having (GSQ46)"&CHAR(10)&"CodeChef · Medium") -> Having (GSQ46) CodeChef · Medium | H11: =HYPERLINK("https://leetcode.com/problems/actors-and-directors-who-cooperated-at-least-three-times/","1050. Actors and Directors Who Cooperated At Least Three Times"&CHAR(10)&"LeetCode · Medium") -> 1050. Actors and Directors Who Cooperated At Least Three Times LeetCode · Medium | I11: =HYPERLINK("https://www.codechef.com/learn/course/sql/SQ00LS09/problems/GSQ47","Problem-Group By & Having (GSQ47)"&CHAR(10)&"CodeChef · Challenging") -> Problem-Group By & Having (GSQ47) CodeChef · Challenging
A12: 11 | B12: Conditional Logic & Dates | C12: CASE Expressions | D12: Searched CASE, CASE in SELECT / ORDER BY, CASE inside aggregates | E12: =HYPERLINK("https://www.hackerrank.com/challenges/what-type-of-triangle/problem","Type of Triangle"&CHAR(10)&"HackerRank · Easy") -> Type of Triangle HackerRank · Easy | F12: =HYPERLINK("https://leetcode.com/problems/triangle-judgement/","610. Triangle Judgement"&CHAR(10)&"LeetCode · Easy") -> 610. Triangle Judgement LeetCode · Easy | G12: =HYPERLINK("https://leetcode.com/problems/calculate-special-bonus/","1873. Calculate Special Bonus"&CHAR(10)&"LeetCode · Medium") -> 1873. Calculate Special Bonus LeetCode · Medium | H12: =HYPERLINK("https://www.codechef.com/learn/course/sql-intermediate/SQ00BS08/problems/GSQ81","Case - When (GSQ81)"&CHAR(10)&"CodeChef · Medium") -> Case - When (GSQ81) CodeChef · Medium | I12: =HYPERLINK("https://www.codechef.com/learn/course/sql-intermediate/SQ00BS08/problems/GSQ83","Sum using Case (GSQ83)"&CHAR(10)&"CodeChef · Medium") -> Sum using Case (GSQ83) CodeChef · Medium
A13: 12 | C13: Date & Time Functions | D13: YEAR / MONTH, DATE_FORMAT / strftime, DATEDIFF / JULIANDAY, date ranges | E13: =HYPERLINK("https://leetcode.com/problems/user-activity-for-the-past-30-days-i/","1141. User Activity for the Past 30 Days I"&CHAR(10)&"LeetCode · Easy") -> 1141. User Activity for the Past 30 Days I LeetCode · Easy | F13: =HYPERLINK("https://leetcode.com/problems/the-latest-login-in-2020/","1890. The Latest Login in 2020"&CHAR(10)&"LeetCode · Easy") -> 1890. The Latest Login in 2020 LeetCode · Easy | G13: =HYPERLINK("https://www.codechef.com/learn/course/sql/BEGSQLPR/problems/RSMSPR06C","Task-6C Aggregations & Grouping (RSMSPR06C)"&CHAR(10)&"CodeChef · Medium") -> Task-6C Aggregations & Grouping (RSMSPR06C) CodeChef · Medium | H13: =HYPERLINK("https://www.codechef.com/learn/course/sql/BEGSQLPR/problems/RSMSPR08","Task-8 Date Functions (RSMSPR08)"&CHAR(10)&"CodeChef · Medium") -> Task-8 Date Functions (RSMSPR08) CodeChef · Medium | I13: =HYPERLINK("https://leetcode.com/problems/monthly-transactions-i/","1193. Monthly Transactions I"&CHAR(10)&"LeetCode · Challenging") -> 1193. Monthly Transactions I LeetCode · Challenging
A14: 13 | C14: Pivoting & Conditional Aggregation | D14: SUM / AVG / COUNT over CASE, rows-to-columns reports, ratios and percentages | E14: =HYPERLINK("https://leetcode.com/problems/reformat-department-table/","1179. Reformat Department Table"&CHAR(10)&"LeetCode · Easy") -> 1179. Reformat Department Table LeetCode · Easy | F14: =HYPERLINK("https://leetcode.com/problems/queries-quality-and-percentage/","1211. Queries Quality and Percentage"&CHAR(10)&"LeetCode · Easy") -> 1211. Queries Quality and Percentage LeetCode · Easy | G14: =HYPERLINK("https://www.codechef.com/learn/course/sql-intermediate/SQ00BS08/problems/GSQ84","Combining Aggregates (GSQ84)"&CHAR(10)&"CodeChef · Medium") -> Combining Aggregates (GSQ84) CodeChef · Medium | H14: =HYPERLINK("https://leetcode.com/problems/capital-gainloss/","1393. Capital Gain/Loss"&CHAR(10)&"LeetCode · Medium") -> 1393. Capital Gain/Loss LeetCode · Medium | I14: =HYPERLINK("https://leetcode.com/problems/odd-and-even-transactions/","3220. Odd and Even Transactions"&CHAR(10)&"LeetCode · Challenging") -> 3220. Odd and Even Transactions LeetCode · Challenging
A15: 14 | B15: Data Modification & Schema | C15: UPDATE & DELETE | D15: UPDATE ... SET ... WHERE, DELETE FROM ... WHERE, UPDATE with CASE | E15: =HYPERLINK("https://www.codechef.com/learn/course/sql/SQ00LS02/problems/GSQ11","Practice Problem - Update table (GSQ11)"&CHAR(10)&"CodeChef · Easy") -> Practice Problem - Update table (GSQ11) CodeChef · Easy | F15: =HYPERLINK("https://www.codechef.com/learn/course/sql/SQ00LS03/problems/GSQ56","Practice - Delete Single Record (GSQ56)"&CHAR(10)&"CodeChef · Easy") -> Practice - Delete Single Record (GSQ56) CodeChef · Easy | G15: =HYPERLINK("https://www.codechef.com/learn/course/sql/SQ00LS02/problems/GSQ14","Practice - Delete From (GSQ14)"&CHAR(10)&"CodeChef · Easy") -> Practice - Delete From (GSQ14) CodeChef · Easy | H15: =HYPERLINK("https://www.codechef.com/learn/course/sql/BEGSQLPR/problems/RSMSPR04C","Task-4C Data Modification (Update and Alter) (RSMSPR04C)"&CHAR(10)&"CodeChef · Medium") -> Task-4C Data Modification (Update and Alter) (RSMSPR04C) CodeChef · Medium | I15: =HYPERLINK("https://leetcode.com/problems/swap-sex-of-employees/","627. Swap Sex of Employees"&CHAR(10)&"LeetCode · Medium") -> 627. Swap Sex of Employees LeetCode · Medium
A16: 15 | C16: ALTER TABLE & Constraints | D16: ADD COLUMN, DEFAULT, PRIMARY KEY, UNIQUE, NOT NULL, CHECK, FOREIGN KEY | E16: =HYPERLINK("https://www.codechef.com/learn/course/sql/SQ00LS02/problems/GSQ10","Practice Problem - Alter table (GSQ10)"&CHAR(10)&"CodeChef · Easy") -> Practice Problem - Alter table (GSQ10) CodeChef · Easy | F16: =HYPERLINK("https://www.codechef.com/learn/course/sql/SQ00LS02/problems/GSQ13","Constraints (GSQ13)"&CHAR(10)&"CodeChef · Easy") -> Constraints (GSQ13) CodeChef · Easy | G16: =HYPERLINK("https://www.codechef.com/learn/course/sql/SQ00LS03/problems/GSQ57","Practice - Create Table with Constraints (GSQ57)"&CHAR(10)&"CodeChef · Medium") -> Practice - Create Table with Constraints (GSQ57) CodeChef · Medium | H16: =HYPERLINK("https://www.codechef.com/learn/course/sql-intermediate/SQ00BS02/problems/SQLKEY01","Foreign Key and Unique Key (SQLKEY01)"&CHAR(10)&"CodeChef · Medium") -> Foreign Key and Unique Key (SQLKEY01) CodeChef · Medium | I16: =HYPERLINK("https://www.codechef.com/learn/course/sql/BEGSQLPR/problems/RSMSPR01","Task-1 Design the Database Schema- Tables & Fields (RSMSPR01)"&CHAR(10)&"CodeChef · Challenging") -> Task-1 Design the Database Schema- Tables & Fields (RSMSPR01) CodeChef · Challenging
A17: 16 | B17: Joins | C17: INNER JOIN | D17: Equi-joins, multi-table joins, non-equi joins | E17: =HYPERLINK("https://leetcode.com/problems/product-sales-analysis-i/","1068. Product Sales Analysis I"&CHAR(10)&"LeetCode · Easy") -> 1068. Product Sales Analysis I LeetCode · Easy | F17: =HYPERLINK("https://www.hackerrank.com/challenges/african-cities/problem","African Cities"&CHAR(10)&"HackerRank · Easy") -> African Cities HackerRank · Easy | G17: =HYPERLINK("https://www.codechef.com/learn/course/sql-intermediate/SQ00BS01/problems/GSQ62","Inner Joins (GSQ62)"&CHAR(10)&"CodeChef · Easy") -> Inner Joins (GSQ62) CodeChef · Easy | H17: =HYPERLINK("https://www.hackerrank.com/challenges/the-report/problem","The Report"&CHAR(10)&"HackerRank · Medium") -> The Report HackerRank · Medium | I17: =HYPERLINK("https://www.hackerrank.com/challenges/full-score/problem","Top Competitors"&CHAR(10)&"HackerRank · Challenging") -> Top Competitors HackerRank · Challenging
A18: 17 | C18: LEFT / RIGHT / FULL OUTER JOIN | D18: Keeping unmatched rows, IS NULL anti-join, IFNULL / COALESCE | E18: =HYPERLINK("https://leetcode.com/problems/combine-two-tables/","175. Combine Two Tables"&CHAR(10)&"LeetCode · Easy") -> 175. Combine Two Tables LeetCode · Easy | F18: =HYPERLINK("https://leetcode.com/problems/replace-employee-id-with-the-unique-identifier/","1378. Replace Employee ID With The Unique Identifier"&CHAR(10)&"LeetCode · Easy") -> 1378. Replace Employee ID With The Unique Identifier LeetCode · Easy | G18: =HYPERLINK("https://www.codechef.com/learn/course/sql-intermediate/SQ00BS01/problems/ASQL01B","Full Outer Joins (ASQL01B)"&CHAR(10)&"CodeChef · Medium") -> Full Outer Joins (ASQL01B) CodeChef · Medium | H18: =HYPERLINK("https://leetcode.com/problems/customer-who-visited-but-did-not-make-any-transactions/","1581. Customer Who Visited but Did Not Make Any Transactions"&CHAR(10)&"LeetCode · Medium") -> 1581. Customer Who Visited but Did Not Make Any Transactions LeetCode · Medium | I18: =HYPERLINK("https://leetcode.com/problems/average-selling-price/","1251. Average Selling Price"&CHAR(10)&"LeetCode · Challenging") -> 1251. Average Selling Price LeetCode · Challenging
A19: 18 | C19: SELF JOIN & CROSS JOIN | D19: Table aliases, comparing rows of the same table, Cartesian product | E19: =HYPERLINK("https://leetcode.com/problems/employees-earning-more-than-their-managers/","181. Employees Earning More Than Their Managers"&CHAR(10)&"LeetCode · Easy") -> 181. Employees Earning More Than Their Managers LeetCode · Easy | F19: =HYPERLINK("https://www.codechef.com/learn/course/sql-intermediate/SQ00BS01/problems/ASQL01C","Self Joins (ASQL01C)"&CHAR(10)&"CodeChef · Easy") -> Self Joins (ASQL01C) CodeChef · Easy | G19: =HYPERLINK("https://leetcode.com/problems/students-and-examinations/","1280. Students and Examinations"&CHAR(10)&"LeetCode · Medium") -> 1280. Students and Examinations LeetCode · Medium | H19: =HYPERLINK("https://leetcode.com/problems/rising-temperature/","197. Rising Temperature"&CHAR(10)&"LeetCode · Medium") -> 197. Rising Temperature LeetCode · Medium | I19: =HYPERLINK("https://www.hackerrank.com/challenges/symmetric-pairs/problem","Symmetric Pairs"&CHAR(10)&"HackerRank · Challenging") -> Symmetric Pairs HackerRank · Challenging
A20: 19 | B20: Subqueries & Set Operations | C20: Subqueries | D20: Scalar subqueries, IN / NOT IN, subqueries in HAVING | E20: =HYPERLINK("https://leetcode.com/problems/employees-whose-manager-left-the-company/","1978. Employees Whose Manager Left the Company"&CHAR(10)&"LeetCode · Easy") -> 1978. Employees Whose Manager Left the Company LeetCode · Easy | F20: =HYPERLINK("https://www.codechef.com/learn/course/sql-intermediate/SQ00BS04/problems/GSQ71","Problem - Non-Correlated Subqueries (GSQ71)"&CHAR(10)&"CodeChef · Easy") -> Problem - Non-Correlated Subqueries (GSQ71) CodeChef · Easy | G20: =HYPERLINK("https://www.hackerrank.com/challenges/binary-search-tree-1/problem","Binary Tree Nodes"&CHAR(10)&"HackerRank · Medium") -> Binary Tree Nodes HackerRank · Medium | H20: =HYPERLINK("https://leetcode.com/problems/second-highest-salary/","176. Second Highest Salary"&CHAR(10)&"LeetCode · Medium") -> 176. Second Highest Salary LeetCode · Medium | I20: =HYPERLINK("https://leetcode.com/problems/customers-who-bought-all-products/","1045. Customers Who Bought All Products"&CHAR(10)&"LeetCode · Challenging") -> 1045. Customers Who Bought All Products LeetCode · Challenging
A21: 20 | C21: Correlated Subqueries & EXISTS | D21: Per-row subqueries, EXISTS / NOT EXISTS | E21: =HYPERLINK("https://leetcode.com/problems/customers-who-never-order/","183. Customers Who Never Order"&CHAR(10)&"LeetCode · Easy") -> 183. Customers Who Never Order LeetCode · Easy | F21: =HYPERLINK("https://leetcode.com/problems/department-highest-salary/","184. Department Highest Salary"&CHAR(10)&"LeetCode · Medium") -> 184. Department Highest Salary LeetCode · Medium | G21: =HYPERLINK("https://leetcode.com/problems/product-price-at-a-given-date/","1164. Product Price at a Given Date"&CHAR(10)&"LeetCode · Medium") -> 1164. Product Price at a Given Date LeetCode · Medium | H21: =HYPERLINK("https://www.hackerrank.com/challenges/harry-potter-and-wands/problem","Ollivander's Inventory"&CHAR(10)&"HackerRank · Challenging") -> Ollivander's Inventory HackerRank · Challenging | I21: =HYPERLINK("https://leetcode.com/problems/department-top-three-salaries/","185. Department Top Three Salaries"&CHAR(10)&"LeetCode · Challenging") -> 185. Department Top Three Salaries LeetCode · Challenging
A22: 21 | C22: Set Operations | D22: UNION / UNION ALL, INTERSECT, EXCEPT | E22: =HYPERLINK("https://www.codechef.com/learn/course/sql-intermediate/SQ00BS02/problems/GSQ66","Union (GSQ66)"&CHAR(10)&"CodeChef · Easy") -> Union (GSQ66) CodeChef · Easy | F22: =HYPERLINK("https://www.codechef.com/learn/course/sql-intermediate/SQ00BS06/problems/GSQ77","Except (GSQ77)"&CHAR(10)&"CodeChef · Easy") -> Except (GSQ77) CodeChef · Easy | G22: =HYPERLINK("https://leetcode.com/problems/rearrange-products-table/","1795. Rearrange Products Table"&CHAR(10)&"LeetCode · Medium") -> 1795. Rearrange Products Table LeetCode · Medium | H22: =HYPERLINK("https://leetcode.com/problems/count-salary-categories/","1907. Count Salary Categories"&CHAR(10)&"LeetCode · Medium") -> 1907. Count Salary Categories LeetCode · Medium | I22: =HYPERLINK("https://leetcode.com/problems/movie-rating/","1341. Movie Rating"&CHAR(10)&"LeetCode · Challenging") -> 1341. Movie Rating LeetCode · Challenging
A23: 22 | B23: Advanced SQL | C23: Common Table Expressions (WITH) | D23: Named subqueries, multi-step queries, derived tables | E23: =HYPERLINK("https://www.codechef.com/learn/course/sql-intermediate/SQ00BS03/problems/GSQ68F","Project - Temporary table with Join (GSQ68F)"&CHAR(10)&"CodeChef · Medium") -> Project - Temporary table with Join (GSQ68F) CodeChef · Medium | F23: =HYPERLINK("https://leetcode.com/problems/product-sales-analysis-iii/","1070. Product Sales Analysis III"&CHAR(10)&"LeetCode · Medium") -> 1070. Product Sales Analysis III LeetCode · Medium | G23: =HYPERLINK("https://www.hackerrank.com/challenges/contest-leaderboard/problem","Contest Leaderboard"&CHAR(10)&"HackerRank · Medium") -> Contest Leaderboard HackerRank · Medium | H23: =HYPERLINK("https://leetcode.com/problems/investments-in-2016/","585. Investments in 2016"&CHAR(10)&"LeetCode · Challenging") -> 585. Investments in 2016 LeetCode · Challenging | I23: =HYPERLINK("https://www.hackerrank.com/challenges/interviews/problem","Interviews"&CHAR(10)&"HackerRank · Challenging") -> Interviews HackerRank · Challenging
A24: 23 | C24: Window Functions – Ranking | D24: ROW_NUMBER, RANK, DENSE_RANK, PARTITION BY | E24: =HYPERLINK("https://leetcode.com/problems/rank-scores/","178. Rank Scores"&CHAR(10)&"LeetCode · Easy") -> 178. Rank Scores LeetCode · Easy | F24: =HYPERLINK("https://www.codechef.com/learn/course/sql-intermediate/JJTST2/problems/ASQLPR112","Task-11 Rank Doctors Based on Patient Feedback (ASQLPR112)"&CHAR(10)&"CodeChef · Medium") -> Task-11 Rank Doctors Based on Patient Feedback (ASQLPR112) CodeChef · Medium | G24: =HYPERLINK("https://www.codechef.com/learn/course/sql-intermediate/JJTST2/problems/ASQLPR113","Task-12 Analyze Treatment Trends Per Department (ASQLPR113)"&CHAR(10)&"CodeChef · Medium") -> Task-12 Analyze Treatment Trends Per Department (ASQLPR113) CodeChef · Medium | H24: =HYPERLINK("https://www.hackerrank.com/challenges/occupations/problem","Occupations"&CHAR(10)&"HackerRank · Challenging") -> Occupations HackerRank · Challenging | I24: =HYPERLINK("https://leetcode.com/problems/seasonal-sales-analysis/","3564. Seasonal Sales Analysis"&CHAR(10)&"LeetCode · Challenging") -> 3564. Seasonal Sales Analysis LeetCode · Challenging
A25: 24 | C25: Window Functions – LAG / LEAD & Running Totals | D25: LAG / LEAD, SUM() OVER, window frames (ROWS BETWEEN), gaps and islands | E25: =HYPERLINK("https://leetcode.com/problems/consecutive-numbers/","180. Consecutive Numbers"&CHAR(10)&"LeetCode · Medium") -> 180. Consecutive Numbers LeetCode · Medium | F25: =HYPERLINK("https://leetcode.com/problems/last-person-to-fit-in-the-bus/","1204. Last Person to Fit in the Bus"&CHAR(10)&"LeetCode · Medium") -> 1204. Last Person to Fit in the Bus LeetCode · Medium | G25: =HYPERLINK("https://leetcode.com/problems/restaurant-growth/","1321. Restaurant Growth"&CHAR(10)&"LeetCode · Medium") -> 1321. Restaurant Growth LeetCode · Medium | H25: =HYPERLINK("https://www.hackerrank.com/challenges/sql-projects/problem","SQL Project Planning"&CHAR(10)&"HackerRank · Challenging") -> SQL Project Planning HackerRank · Challenging | I25: =HYPERLINK("https://leetcode.com/problems/human-traffic-of-stadium/","601. Human Traffic of Stadium"&CHAR(10)&"LeetCode · Challenging") -> 601. Human Traffic of Stadium LeetCode · Challenging
A26: 25 | C26: Recursive CTEs | D26: WITH RECURSIVE, generating rows / numbers, walking hierarchies | E26: =HYPERLINK("https://www.hackerrank.com/challenges/draw-the-triangle-1/problem","Draw The Triangle 1"&CHAR(10)&"HackerRank · Easy") -> Draw The Triangle 1 HackerRank · Easy | F26: =HYPERLINK("https://www.hackerrank.com/challenges/draw-the-triangle-2/problem","Draw The Triangle 2"&CHAR(10)&"HackerRank · Easy") -> Draw The Triangle 2 HackerRank · Easy | G26: =HYPERLINK("https://www.hackerrank.com/challenges/print-prime-numbers/problem","Print Prime Numbers"&CHAR(10)&"HackerRank · Medium") -> Print Prime Numbers HackerRank · Medium | H26: =HYPERLINK("https://leetcode.com/problems/analyze-organization-hierarchy/","3482. Analyze Organization Hierarchy"&CHAR(10)&"LeetCode · Challenging") -> 3482. Analyze Organization Hierarchy LeetCode · Challenging | I26: Not available – see Validation Report
A27: 26 | C27: Stored Functions & Procedures | D27: CREATE FUNCTION, parameters, RETURN | E27: =HYPERLINK("https://leetcode.com/problems/nth-highest-salary/","177. Nth Highest Salary"&CHAR(10)&"LeetCode · Medium") -> 177. Nth Highest Salary LeetCode · Medium | F27: Not available – see Validation Report | G27: Not available – see Validation Report | H27: Not available – see Validation Report | I27: Not available – see Validation Report
B29: Legend
B30: LeetCode problem | D30: Each cell links to the problem. The second line shows the platform and the level within the topic (Q1 easiest → Q5 hardest). Every problem needs only the current topic and earlier ones. Full details are in 'Question Bank Details'.
B31: HackerRank challenge
B32: CodeChef problem
B33: Not available – see Validation Report

Sheet Question Bank Details
A1: # | B1: Section | C1: Topic | D1: Q# | E1: Question Title | F1: Platform | G1: Difficulty | H1: Problem URL | I1: Free Access | J1: Primary Concept | K1: Prerequisite Concepts | L1: Topic Boundary Verified | M1: Status | N1: Counts as Valid | O1: Matrix Cell | P1: Notes (SQL engine / context)
A2: 1 | B2: SQL Basics | C2: SELECT & Column Aliases | D2: Q1 | E2: Select All | F2: HackerRank | G2: Easy (HackerRank: Easy) | H2: =HYPERLINK("https://www.hackerrank.com/challenges/select-all-sql/problem","https://www.hackerrank.com/challenges/select-all-sql/problem") -> https://www.hackerrank.com/challenges/select-all-sql/problem | I2: Yes – free; free HackerRank account to submit | J2: SELECT * (all columns) | K2: None (first topic) | L2: Yes – SELECT * FROM CITY | M2: Added (verified) | N2: =IF(M2="Added (verified)","Yes","No") -> Yes | O2: E2 | P2: Engines: MySQL, MS SQL Server, Oracle, DB2.
A3: 1 | B3: SQL Basics | C3: SELECT & Column Aliases | D3: Q2 | E3: Weather Observation Station 1 | F3: HackerRank | G3: Easy (HackerRank: Easy) | H3: =HYPERLINK("https://www.hackerrank.com/challenges/weather-observation-station-1/problem","https://www.hackerrank.com/challenges/weather-observation-station-1/problem") -> https://www.hackerrank.com/challenges/weather-observation-station-1/problem | I3: Yes – free; free HackerRank account to submit | J3: Selecting specific columns | K3: None (first topic) | L3: Yes – SELECT CITY, STATE FROM STATION | M3: Added (verified) | N3: =IF(M3="Added (verified)","Yes","No") -> Yes | O3: F2 | P3: Engines: MySQL, MS SQL Server, Oracle, DB2.
A4: 1 | B4: SQL Basics | C4: SELECT & Column Aliases | D4: Q3 | E4: All Products (SQLPBP11) | F4: CodeChef | G4: Easy (CodeChef: easy) | H4: =HYPERLINK("https://www.codechef.com/practice/course/sql-case-studies-topic-wise/SQLBP01/problems/SQLPBP11","https://www.codechef.com/practice/course/sql-case-studies-topic-wise/SQLBP01/problems/SQLPBP11") -> https://www.codechef.com/practice/course/sql-case-studies-topic-wise/SQLBP01/problems/SQLPBP11 | I4: Yes – free (non-Pro) module of CodeChef 'SQL Practice Queries'; free account to submit | J4: SELECT * from a named table | K4: None (first topic) | L4: Yes – outputs the whole Products table | M4: Added (verified) | N4: =IF(M4="Added (verified)","Yes","No") -> Yes | O4: G2 | P4: Module 'Practice Basic Commands'. MySQL syntax.
A5: 1 | B5: SQL Basics | C5: SELECT & Column Aliases | D5: Q4 | E5: SELECT Query (GSQ17) | F5: CodeChef | G5: Easy (CodeChef: easy) | H5: =HYPERLINK("https://www.codechef.com/learn/course/sql/SQ00LS04/problems/GSQ17","https://www.codechef.com/learn/course/sql/SQ00LS04/problems/GSQ17") -> https://www.codechef.com/learn/course/sql/SQ00LS04/problems/GSQ17 | I5: Yes – free (non-Pro) lesson of CodeChef 'Learn SQL'; free account to submit | J5: Selecting specific columns | K5: None (first topic) | L5: Yes – SELECT passenger_name, gender FROM flights | M5: Added (verified) | N5: =IF(M5="Added (verified)","Yes","No") -> Yes | O5: H2 | P5: Runs on SQLite.
A6: 1 | B6: SQL Basics | C6: SELECT & Column Aliases | D6: Q5 | E6: Rename columns using As (GSQ37A) | F6: CodeChef | G6: Easy (CodeChef: easy) | H6: =HYPERLINK("https://www.codechef.com/learn/course/sql/SQ00LS08/problems/GSQ37A","https://www.codechef.com/learn/course/sql/SQ00LS08/problems/GSQ37A") -> https://www.codechef.com/learn/course/sql/SQ00LS08/problems/GSQ37A | I6: Yes – free (non-Pro) lesson of CodeChef 'Learn SQL'; free account to submit | J6: Column aliases with AS | K6: Selecting columns | L6: Yes – three columns renamed with AS; no filtering or functions | M6: Added (verified) | N6: =IF(M6="Added (verified)","Yes","No") -> Yes | O6: I2 | P6: Runs on SQLite.
A7: 2 | B7: SQL Basics | C7: CREATE TABLE & INSERT INTO | D7: Q1 | E7: Create table (GSQ04) | F7: CodeChef | G7: Easy (CodeChef: easy) | H7: =HYPERLINK("https://www.codechef.com/learn/course/sql/SQ00LS01/problems/GSQ04","https://www.codechef.com/learn/course/sql/SQ00LS01/problems/GSQ04") -> https://www.codechef.com/learn/course/sql/SQ00LS01/problems/GSQ04 | I7: Yes – free (non-Pro) lesson of CodeChef 'Learn SQL'; free account to submit | J7: CREATE TABLE with column data types | K7: None | L7: Yes – one CREATE TABLE statement | M7: Added (verified) | N7: =IF(M7="Added (verified)","Yes","No") -> Yes | O7: E3 | P7: Runs on SQLite.
A8: 2 | B8: SQL Basics | C8: CREATE TABLE & INSERT INTO | D8: Q2 | E8: How to insert to a table (GSQ07) | F8: CodeChef | G8: Easy (CodeChef: easy) | H8: =HYPERLINK("https://www.codechef.com/learn/course/sql/SQ00LS01/problems/GSQ07","https://www.codechef.com/learn/course/sql/SQ00LS01/problems/GSQ07") -> https://www.codechef.com/learn/course/sql/SQ00LS01/problems/GSQ07 | I8: Yes – free (non-Pro) lesson of CodeChef 'Learn SQL'; free account to submit | J8: INSERT INTO ... VALUES (one row) | K8: CREATE TABLE | L8: Yes – one INSERT statement | M8: Added (verified) | N8: =IF(M8="Added (verified)","Yes","No") -> Yes | O8: F3 | P8: The employee table from the previous lesson is pre-loaded. Runs on SQLite.
A9: 2 | B9: SQL Basics | C9: CREATE TABLE & INSERT INTO | D9: Q3 | E9: Inserting Data into a Table (GSQ05) | F9: CodeChef | G9: Easy (CodeChef: easy) | H9: =HYPERLINK("https://www.codechef.com/learn/course/sql/SQ00LS01/problems/GSQ05","https://www.codechef.com/learn/course/sql/SQ00LS01/problems/GSQ05") -> https://www.codechef.com/learn/course/sql/SQ00LS01/problems/GSQ05 | I9: Yes – free (non-Pro) lesson of CodeChef 'Learn SQL'; free account to submit | J9: Multi-row INSERT | K9: CREATE TABLE, INSERT | L9: Yes – one INSERT with two value lists | M9: Added (verified) | N9: =IF(M9="Added (verified)","Yes","No") -> Yes | O9: G3 | P9: Runs on SQLite.
A10: 2 | B10: SQL Basics | C10: CREATE TABLE & INSERT INTO | D10: Q4 | E10: Debug this query (GSQ06) | F10: CodeChef | G10: Medium (CodeChef: easy) | H10: =HYPERLINK("https://www.codechef.com/learn/course/sql/SQ00LS01/problems/GSQ06","https://www.codechef.com/learn/course/sql/SQ00LS01/problems/GSQ06") -> https://www.codechef.com/learn/course/sql/SQ00LS01/problems/GSQ06 | I10: Yes – free (non-Pro) lesson of CodeChef 'Learn SQL'; free account to submit | J10: Fixing a broken INSERT statement | K10: T1 SELECT * | L10: Yes – corrected INSERT, then SELECT * (Topic 1) | M10: Added (verified) | N10: =IF(M10="Added (verified)","Yes","No") -> Yes | O10: H3 | P10: Runs on SQLite.
A11: 2 | B11: SQL Basics | C11: CREATE TABLE & INSERT INTO | D11: Q5 | E11: Project - Customer Database (GSQ53) | F11: CodeChef | G11: Medium (CodeChef: easy) | H11: =HYPERLINK("https://www.codechef.com/learn/course/sql/SQ00LS03/problems/GSQ53","https://www.codechef.com/learn/course/sql/SQ00LS03/problems/GSQ53") -> https://www.codechef.com/learn/course/sql/SQ00LS03/problems/GSQ53 | I11: Yes – free (non-Pro) lesson of CodeChef 'Learn SQL'; free account to submit | J11: CREATE TABLE + INSERT five rows + display the table | K11: T1 SELECT * | L11: Yes – CREATE, INSERT and SELECT * only | M11: Added (verified) | N11: =IF(M11="Added (verified)","Yes","No") -> Yes | O11: I3 | P11: Runs on SQLite.
A12: 3 | B12: SQL Basics | C12: Filtering with WHERE | D12: Q1 | E12: 1757. Recyclable and Low Fat Products | F12: LeetCode | G12: Easy (LeetCode: Easy) | H12: =HYPERLINK("https://leetcode.com/problems/recyclable-and-low-fat-products/","https://leetcode.com/problems/recyclable-and-low-fat-products/") -> https://leetcode.com/problems/recyclable-and-low-fat-products/ | I12: Yes – free problem (not Premium); free LeetCode account to submit | J12: WHERE with AND | K12: T1 SELECT | L12: Yes – WHERE low_fats = 'Y' AND recyclable = 'Y' | M12: Added (verified) | N12: =IF(M12="Added (verified)","Yes","No") -> Yes | O12: E4 | P12: Engines: MySQL, MS SQL Server, Oracle, PostgreSQL.
A13: 3 | B13: SQL Basics | C13: Filtering with WHERE | D13: Q2 | E13: Revising the Select Query I | F13: HackerRank | G13: Easy (HackerRank: Easy) | H13: =HYPERLINK("https://www.hackerrank.com/challenges/revising-the-select-query/problem","https://www.hackerrank.com/challenges/revising-the-select-query/problem") -> https://www.hackerrank.com/challenges/revising-the-select-query/problem | I13: Yes – free; free HackerRank account to submit | J13: WHERE with = and > combined by AND | K13: T1 SELECT | L13: Yes – WHERE CountryCode = 'USA' AND Population > 100000 | M13: Added (verified) | N13: =IF(M13="Added (verified)","Yes","No") -> Yes | O13: F4 | P13: Engines: MySQL, MS SQL Server, Oracle, DB2.
A14: 3 | B14: SQL Basics | C14: Filtering with WHERE | D14: Q3 | E14: High Price of Products (SQLPBP12) | F14: CodeChef | G14: Easy (CodeChef: easy) | H14: =HYPERLINK("https://www.codechef.com/practice/course/sql-case-studies-topic-wise/SQLBP01/problems/SQLPBP12","https://www.codechef.com/practice/course/sql-case-studies-topic-wise/SQLBP01/problems/SQLPBP12") -> https://www.codechef.com/practice/course/sql-case-studies-topic-wise/SQLBP01/problems/SQLPBP12 | I14: Yes – free (non-Pro) module of CodeChef 'SQL Practice Queries'; free account to submit | J14: WHERE with a > comparison | K14: T1 SELECT | L14: Yes – WHERE price > 100.00 | M14: Added (verified) | N14: =IF(M14="Added (verified)","Yes","No") -> Yes | O14: G4 | P14: Module 'Practice Basic Commands'. MySQL syntax.
A15: 3 | B15: SQL Basics | C15: Filtering with WHERE | D15: Q4 | E15: Handling NULL Values (SQLPBP07) | F15: CodeChef | G15: Easy (CodeChef: easy) | H15: =HYPERLINK("https://www.codechef.com/practice/course/sql-case-studies-topic-wise/SQLBP01/problems/SQLPBP07","https://www.codechef.com/practice/course/sql-case-studies-topic-wise/SQLBP01/problems/SQLPBP07") -> https://www.codechef.com/practice/course/sql-case-studies-topic-wise/SQLBP01/problems/SQLPBP07 | I15: Yes – free (non-Pro) module of CodeChef 'SQL Practice Queries'; free account to submit | J15: IS NULL | K15: T1 SELECT | L15: Yes – WHERE rating IS NULL | M15: Added (verified) | N15: =IF(M15="Added (verified)","Yes","No") -> Yes | O15: H4 | P15: Module 'Practice Basic Commands'. MySQL syntax.
A16: 3 | B16: SQL Basics | C16: Filtering with WHERE | D16: Q5 | E16: 584. Find Customer Referee | F16: LeetCode | G16: Medium (LeetCode: Easy) | H16: =HYPERLINK("https://leetcode.com/problems/find-customer-referee/","https://leetcode.com/problems/find-customer-referee/") -> https://leetcode.com/problems/find-customer-referee/ | I16: Yes – free problem (not Premium); free LeetCode account to submit | J16: NULL-aware filtering (<> plus OR ... IS NULL) | K16: T1 SELECT | L16: Yes – WHERE referee_id <> 2 OR referee_id IS NULL | M16: Added (verified) | N16: =IF(M16="Added (verified)","Yes","No") -> Yes | O16: I4 | P16: Engines: MySQL, MS SQL Server, Oracle, PostgreSQL.
A17: 4 | B17: SQL Basics | C17: DISTINCT, ORDER BY & LIMIT | D17: Q1 | E17: Distinct Companies (SQLPBP13) | F17: CodeChef | G17: Easy (CodeChef: easy) | H17: =HYPERLINK("https://www.codechef.com/practice/course/sql-case-studies-topic-wise/SQLBP01/problems/SQLPBP13","https://www.codechef.com/practice/course/sql-case-studies-topic-wise/SQLBP01/problems/SQLPBP13") -> https://www.codechef.com/practice/course/sql-case-studies-topic-wise/SQLBP01/problems/SQLPBP13 | I17: Yes – free (non-Pro) module of CodeChef 'SQL Practice Queries'; free account to submit | J17: SELECT DISTINCT | K17: T1 SELECT | L17: Yes – SELECT DISTINCT company_name FROM Works | M17: Added (verified) | N17: =IF(M17="Added (verified)","Yes","No") -> Yes | O17: E5 | P17: Module 'Practice Basic Commands'. MySQL syntax.
A18: 4 | B18: SQL Basics | C18: DISTINCT, ORDER BY & LIMIT | D18: Q2 | E18: Employee Names | F18: HackerRank | G18: Easy (HackerRank: Easy) | H18: =HYPERLINK("https://www.hackerrank.com/challenges/name-of-employees/problem","https://www.hackerrank.com/challenges/name-of-employees/problem") -> https://www.hackerrank.com/challenges/name-of-employees/problem | I18: Yes – free; free HackerRank account to submit | J18: ORDER BY (alphabetical) | K18: T1 SELECT | L18: Yes – SELECT name FROM Employee ORDER BY name | M18: Added (verified) | N18: =IF(M18="Added (verified)","Yes","No") -> Yes | O18: F5 | P18: Engines: MySQL, MS SQL Server, Oracle, DB2.
A19: 4 | B19: SQL Basics | C19: DISTINCT, ORDER BY & LIMIT | D19: Q3 | E19: 1148. Article Views I | F19: LeetCode | G19: Easy (LeetCode: Easy) | H19: =HYPERLINK("https://leetcode.com/problems/article-views-i/","https://leetcode.com/problems/article-views-i/") -> https://leetcode.com/problems/article-views-i/ | I19: Yes – free problem (not Premium); free LeetCode account to submit | J19: DISTINCT + ORDER BY after a WHERE filter | K19: T1, T3 WHERE | L19: Yes – SELECT DISTINCT author_id ... WHERE author_id = viewer_id ORDER BY id | M19: Added (verified) | N19: =IF(M19="Added (verified)","Yes","No") -> Yes | O19: G5 | P19: Engines: MySQL, MS SQL Server, Oracle, PostgreSQL.
A20: 4 | B20: SQL Basics | C20: DISTINCT, ORDER BY & LIMIT | D20: Q4 | E20: Employee Salaries | F20: HackerRank | G20: Medium (HackerRank: Easy) | H20: =HYPERLINK("https://www.hackerrank.com/challenges/salary-of-employees/problem","https://www.hackerrank.com/challenges/salary-of-employees/problem") -> https://www.hackerrank.com/challenges/salary-of-employees/problem | I20: Yes – free; free HackerRank account to submit | J20: Filter, then sort by a key | K20: T3 WHERE | L20: Yes – WHERE salary > 2000 AND months < 10 ORDER BY employee_id | M20: Added (verified) | N20: =IF(M20="Added (verified)","Yes","No") -> Yes | O20: H5 | P20: Engines: MySQL, MS SQL Server, Oracle, DB2.
A21: 4 | B21: SQL Basics | C21: DISTINCT, ORDER BY & LIMIT | D21: Q5 | E21: Task-3C Data Retrieval Using Queries (RSMSPR03C) | F21: CodeChef | G21: Medium (CodeChef: easy) | H21: =HYPERLINK("https://www.codechef.com/learn/course/sql/BEGSQLPR/problems/RSMSPR03C","https://www.codechef.com/learn/course/sql/BEGSQLPR/problems/RSMSPR03C") -> https://www.codechef.com/learn/course/sql/BEGSQLPR/problems/RSMSPR03C | I21: Yes – free (non-Pro) lesson of CodeChef 'Learn SQL'; free account to submit | J21: Top-N with ORDER BY ... DESC LIMIT | K21: T1 SELECT | L21: Yes – ORDER BY price DESC LIMIT 2 | M21: Added (verified) | N21: =IF(M21="Added (verified)","Yes","No") -> Yes | O21: I5 | P21: Lesson of the free 'Retail store management system' project; the tables it needs are pre-loaded and shown in the statement. Runs on SQLite.
A22: 5 | B22: SQL Basics | C22: BETWEEN, IN & LIKE | D22: Q1 | E22: BETWEEN (GSQ19A) | F22: CodeChef | G22: Easy (CodeChef: easy) | H22: =HYPERLINK("https://www.codechef.com/learn/course/sql/SQ00LS04/problems/GSQ19A","https://www.codechef.com/learn/course/sql/SQ00LS04/problems/GSQ19A") -> https://www.codechef.com/learn/course/sql/SQ00LS04/problems/GSQ19A | I22: Yes – free (non-Pro) lesson of CodeChef 'Learn SQL'; free account to submit | J22: BETWEEN ... AND ... | K22: T1, T3 WHERE | L22: Yes – WHERE passenger_name BETWEEN 'A' AND 'D' | M22: Added (verified) | N22: =IF(M22="Added (verified)","Yes","No") -> Yes | O22: E6 | P22: Runs on SQLite.
A23: 5 | B23: SQL Basics | C23: BETWEEN, IN & LIKE | D23: Q2 | E23: Practice - Filter with multiple Like patterns (GSQ26) | F23: CodeChef | G23: Easy (CodeChef: easy) | H23: =HYPERLINK("https://www.codechef.com/learn/course/sql/SQ00LS05/problems/GSQ26","https://www.codechef.com/learn/course/sql/SQ00LS05/problems/GSQ26") -> https://www.codechef.com/learn/course/sql/SQ00LS05/problems/GSQ26 | I23: Yes – free (non-Pro) lesson of CodeChef 'Learn SQL'; free account to submit | J23: LIKE with % wildcards combined by AND | K23: T3 WHERE / AND | L23: Yes – destination LIKE '%o' AND origin LIKE 'M%' | M23: Added (verified) | N23: =IF(M23="Added (verified)","Yes","No") -> Yes | O23: F6 | P23: Runs on SQLite.
A24: 5 | B24: SQL Basics | C24: BETWEEN, IN & LIKE | D24: Q3 | E24: 1527. Patients With a Condition | F24: LeetCode | G24: Medium (LeetCode: Easy) | H24: =HYPERLINK("https://leetcode.com/problems/patients-with-a-condition/","https://leetcode.com/problems/patients-with-a-condition/") -> https://leetcode.com/problems/patients-with-a-condition/ | I24: Yes – free problem (not Premium); free LeetCode account to submit | J24: LIKE on a word inside a space-separated list | K24: T3 OR | L24: Yes – conditions LIKE 'DIAB1%' OR conditions LIKE '% DIAB1%' | M24: Added (verified) | N24: =IF(M24="Added (verified)","Yes","No") -> Yes | O24: G6 | P24: Engines: MySQL, MS SQL Server, Oracle, PostgreSQL.
A25: 5 | B25: SQL Basics | C25: BETWEEN, IN & LIKE | D25: Q4 | E25: Weather Observation Station 6 | F25: HackerRank | G25: Medium (HackerRank: Easy) | H25: =HYPERLINK("https://www.hackerrank.com/challenges/weather-observation-station-6/problem","https://www.hackerrank.com/challenges/weather-observation-station-6/problem") -> https://www.hackerrank.com/challenges/weather-observation-station-6/problem | I25: Yes – free; free HackerRank account to submit | J25: LIKE patterns for a first letter + DISTINCT | K25: T3 OR, T4 DISTINCT | L25: Yes – five OR'ed LIKE patterns ('a%', 'e%', ...) with DISTINCT (Topic 4) | M25: Added (verified) | N25: =IF(M25="Added (verified)","Yes","No") -> Yes | O25: H6 | P25: Engines: MySQL, MS SQL Server, Oracle, DB2.
A26: 5 | B26: SQL Basics | C26: BETWEEN, IN & LIKE | D26: Q5 | E26: Weather Observation Station 12 | F26: HackerRank | G26: Challenging (HackerRank: Easy) | H26: =HYPERLINK("https://www.hackerrank.com/challenges/weather-observation-station-12/problem","https://www.hackerrank.com/challenges/weather-observation-station-12/problem") -> https://www.hackerrank.com/challenges/weather-observation-station-12/problem | I26: Yes – free; free HackerRank account to submit | J26: NOT LIKE on first and last letters + DISTINCT | K26: T3 AND, T4 DISTINCT | L26: Yes – NOT LIKE patterns for both ends with DISTINCT (Topic 4) | M26: Added (verified) | N26: =IF(M26="Added (verified)","Yes","No") -> Yes | O26: I6 | P26: Engines: MySQL, MS SQL Server, Oracle, DB2.
A27: 6 | B27: Functions & Aggregation | C27: String Functions | D27: Q1 | E27: 1683. Invalid Tweets | F27: LeetCode | G27: Easy (LeetCode: Easy) | H27: =HYPERLINK("https://leetcode.com/problems/invalid-tweets/","https://leetcode.com/problems/invalid-tweets/") -> https://leetcode.com/problems/invalid-tweets/ | I27: Yes – free problem (not Premium); free LeetCode account to submit | J27: LENGTH() / CHAR_LENGTH() | K27: T3 WHERE | L27: Yes – WHERE CHAR_LENGTH(content) > 15 | M27: Added (verified) | N27: =IF(M27="Added (verified)","Yes","No") -> Yes | O27: E7 | P27: Engines: MySQL, MS SQL Server, Oracle, PostgreSQL.
A28: 6 | B28: Functions & Aggregation | C28: String Functions | D28: Q2 | E28: Higher Than 75 Marks | F28: HackerRank | G28: Easy (HackerRank: Easy) | H28: =HYPERLINK("https://www.hackerrank.com/challenges/more-than-75-marks/problem","https://www.hackerrank.com/challenges/more-than-75-marks/problem") -> https://www.hackerrank.com/challenges/more-than-75-marks/problem | I28: Yes – free; free HackerRank account to submit | J28: RIGHT() / SUBSTRING() as a sort key | K28: T3 WHERE, T4 ORDER BY | L28: Yes – WHERE Marks > 75 ORDER BY RIGHT(Name, 3), ID | M28: Added (verified) | N28: =IF(M28="Added (verified)","Yes","No") -> Yes | O28: F7 | P28: Engines: MySQL, MS SQL Server, Oracle, DB2.
A29: 6 | B29: Functions & Aggregation | C29: String Functions | D29: Q3 | E29: 1667. Fix Names in a Table | F29: LeetCode | G29: Medium (LeetCode: Easy) | H29: =HYPERLINK("https://leetcode.com/problems/fix-names-in-a-table/","https://leetcode.com/problems/fix-names-in-a-table/") -> https://leetcode.com/problems/fix-names-in-a-table/ | I29: Yes – free problem (not Premium); free LeetCode account to submit | J29: UPPER, LOWER, SUBSTRING and CONCAT together | K29: T4 ORDER BY | L29: Yes – CONCAT(UPPER(LEFT(name,1)), LOWER(SUBSTRING(name,2))) ... ORDER BY user_id | M29: Added (verified) | N29: =IF(M29="Added (verified)","Yes","No") -> Yes | O29: G7 | P29: Engines: MySQL, MS SQL Server, Oracle, PostgreSQL.
A30: 6 | B30: Functions & Aggregation | C30: String Functions | D30: Q4 | E30: Weather Observation Station 5 | F30: HackerRank | G30: Medium (HackerRank: Easy) | H30: =HYPERLINK("https://www.hackerrank.com/challenges/weather-observation-station-5/problem","https://www.hackerrank.com/challenges/weather-observation-station-5/problem") -> https://www.hackerrank.com/challenges/weather-observation-station-5/problem | I30: Yes – free; free HackerRank account to submit | J30: LENGTH() as a sort key with LIMIT 1 | K30: T4 ORDER BY / LIMIT | L30: Yes – two separate SELECTs, each ORDER BY LENGTH(CITY), CITY LIMIT 1 (UNION not needed) | M30: Added (verified) | N30: =IF(M30="Added (verified)","Yes","No") -> Yes | O30: H7 | P30: Engines: MySQL, MS SQL Server, Oracle, DB2.
A31: 6 | B31: Functions & Aggregation | C31: String Functions | D31: Q5 | E31: 1517. Find Users With Valid E-Mails | F31: LeetCode | G31: Challenging (LeetCode: Easy) | H31: =HYPERLINK("https://leetcode.com/problems/find-users-with-valid-e-mails/","https://leetcode.com/problems/find-users-with-valid-e-mails/") -> https://leetcode.com/problems/find-users-with-valid-e-mails/ | I31: Yes – free problem (not Premium); free LeetCode account to submit | J31: Regular-expression matching (REGEXP / REGEXP_LIKE) | K31: T3 WHERE, T5 LIKE | L31: Yes – one REGEXP condition in WHERE | M31: Added (verified) | N31: =IF(M31="Added (verified)","Yes","No") -> Yes | O31: I7 | P31: Engines: MySQL, MS SQL Server, Oracle, PostgreSQL.
A32: 7 | B32: Functions & Aggregation | C32: Aggregate Functions | D32: Q1 | E32: Revising Aggregations - The Count Function | F32: HackerRank | G32: Easy (HackerRank: Easy) | H32: =HYPERLINK("https://www.hackerrank.com/challenges/revising-aggregations-the-count-function/problem","https://www.hackerrank.com/challenges/revising-aggregations-the-count-function/problem") -> https://www.hackerrank.com/challenges/revising-aggregations-the-count-function/problem | I32: Yes – free; free HackerRank account to submit | J32: COUNT() with WHERE | K32: T3 WHERE | L32: Yes – SELECT COUNT(*) ... WHERE Population > 100000 | M32: Added (verified) | N32: =IF(M32="Added (verified)","Yes","No") -> Yes | O32: E8 | P32: Engines: MySQL, MS SQL Server, Oracle, DB2.
A33: 7 | B33: Functions & Aggregation | C33: Aggregate Functions | D33: Q2 | E33: Fiction Collection Size (SQLPBP02) | F33: CodeChef | G33: Easy (CodeChef: easy) | H33: =HYPERLINK("https://www.codechef.com/practice/course/sql-case-studies-topic-wise/SQLBP01/problems/SQLPBP02","https://www.codechef.com/practice/course/sql-case-studies-topic-wise/SQLBP01/problems/SQLPBP02") -> https://www.codechef.com/practice/course/sql-case-studies-topic-wise/SQLBP01/problems/SQLPBP02 | I33: Yes – free (non-Pro) module of CodeChef 'SQL Practice Queries'; free account to submit | J33: COUNT() with WHERE and an alias | K33: T1 AS, T3 WHERE | L33: Yes – COUNT(*) AS fiction_count ... WHERE genre = 'Fiction' | M33: Added (verified) | N33: =IF(M33="Added (verified)","Yes","No") -> Yes | O33: F8 | P33: Module 'Practice Basic Commands'. MySQL syntax.
A34: 7 | B34: Functions & Aggregation | C34: Aggregate Functions | D34: Q3 | E34: Average Salary (SQLPBP14) | F34: CodeChef | G34: Easy (CodeChef: easy) | H34: =HYPERLINK("https://www.codechef.com/practice/course/sql-case-studies-topic-wise/SQLBP01/problems/SQLPBP14","https://www.codechef.com/practice/course/sql-case-studies-topic-wise/SQLBP01/problems/SQLPBP14") -> https://www.codechef.com/practice/course/sql-case-studies-topic-wise/SQLBP01/problems/SQLPBP14 | I34: Yes – free (non-Pro) module of CodeChef 'SQL Practice Queries'; free account to submit | J34: AVG() over the whole table | K34: T1 AS | L34: Yes – SELECT AVG(salary) AS avg_salary FROM Works | M34: Added (verified) | N34: =IF(M34="Added (verified)","Yes","No") -> Yes | O34: G8 | P34: Module 'Practice Basic Commands'. MySQL syntax.
A35: 7 | B35: Functions & Aggregation | C35: Aggregate Functions | D35: Q4 | E35: Problem - SUM() and AVG() (GSQ44) | F35: CodeChef | G35: Medium (CodeChef: easy) | H35: =HYPERLINK("https://www.codechef.com/learn/course/sql/SQ00LS09/problems/GSQ44","https://www.codechef.com/learn/course/sql/SQ00LS09/problems/GSQ44") -> https://www.codechef.com/learn/course/sql/SQ00LS09/problems/GSQ44 | I35: Yes – free (non-Pro) lesson of CodeChef 'Learn SQL'; free account to submit | J35: SUM() and AVG() with WHERE | K35: T1 AS, T3 WHERE | L35: Yes – two SELECTs using SUM / AVG with WHERE | M35: Added (verified) | N35: =IF(M35="Added (verified)","Yes","No") -> Yes | O35: H8 | P35: Runs on SQLite.
A36: 7 | B36: Functions & Aggregation | C36: Aggregate Functions | D36: Q5 | E36: Population Density Difference | F36: HackerRank | G36: Medium (HackerRank: Easy) | H36: =HYPERLINK("https://www.hackerrank.com/challenges/population-density-difference/problem","https://www.hackerrank.com/challenges/population-density-difference/problem") -> https://www.hackerrank.com/challenges/population-density-difference/problem | I36: Yes – free; free HackerRank account to submit | J36: Arithmetic on two aggregates (MAX − MIN) | K36: T1 SELECT | L36: Yes – SELECT MAX(Population) - MIN(Population) | M36: Added (verified) | N36: =IF(M36="Added (verified)","Yes","No") -> Yes | O36: I8 | P36: Engines: MySQL, MS SQL Server, Oracle, DB2.
A37: 8 | B37: Functions & Aggregation | C37: Numeric Functions | D37: Q1 | E37: Weather Observation Station 3 | F37: HackerRank | G37: Easy (HackerRank: Easy) | H37: =HYPERLINK("https://www.hackerrank.com/challenges/weather-observation-station-3/problem","https://www.hackerrank.com/challenges/weather-observation-station-3/problem") -> https://www.hackerrank.com/challenges/weather-observation-station-3/problem | I37: Yes – free; free HackerRank account to submit | J37: MOD() / % to test even numbers | K37: T3 WHERE, T4 DISTINCT | L37: Yes – SELECT DISTINCT CITY ... WHERE MOD(ID, 2) = 0 | M37: Added (verified) | N37: =IF(M37="Added (verified)","Yes","No") -> Yes | O37: E9 | P37: Engines: MySQL, MS SQL Server, Oracle, DB2.
A38: 8 | B38: Functions & Aggregation | C38: Numeric Functions | D38: Q2 | E38: 620. Not Boring Movies | F38: LeetCode | G38: Easy (LeetCode: Easy) | H38: =HYPERLINK("https://leetcode.com/problems/not-boring-movies/","https://leetcode.com/problems/not-boring-movies/") -> https://leetcode.com/problems/not-boring-movies/ | I38: Yes – free problem (not Premium); free LeetCode account to submit | J38: MOD() for odd ids + sorting | K38: T3 WHERE, T4 ORDER BY | L38: Yes – WHERE MOD(id, 2) = 1 AND description <> 'boring' ORDER BY rating DESC | M38: Added (verified) | N38: =IF(M38="Added (verified)","Yes","No") -> Yes | O38: F9 | P38: Engines: MySQL, MS SQL Server, Oracle, PostgreSQL.
A39: 8 | B39: Functions & Aggregation | C39: Numeric Functions | D39: Q3 | E39: Problem-ROUND() (GSQ41) | F39: CodeChef | G39: Easy (CodeChef: easy) | H39: =HYPERLINK("https://www.codechef.com/learn/course/sql/SQ00LS08/problems/GSQ41","https://www.codechef.com/learn/course/sql/SQ00LS08/problems/GSQ41") -> https://www.codechef.com/learn/course/sql/SQ00LS08/problems/GSQ41 | I39: Yes – free (non-Pro) lesson of CodeChef 'Learn SQL'; free account to submit | J39: ROUND() to 2 decimal places | K39: T1 AS | L39: Yes – SELECT ROUND(Payout, 2) AS payout | M39: Added (verified) | N39: =IF(M39="Added (verified)","Yes","No") -> Yes | O39: G9 | P39: Runs on SQLite.
A40: 8 | B40: Functions & Aggregation | C40: Numeric Functions | D40: Q4 | E40: The Blunder | F40: HackerRank | G40: Medium (HackerRank: Easy) | H40: =HYPERLINK("https://www.hackerrank.com/challenges/the-blunder/problem","https://www.hackerrank.com/challenges/the-blunder/problem") -> https://www.hackerrank.com/challenges/the-blunder/problem | I40: Yes – free; free HackerRank account to submit | J40: CEIL() of a difference of averages | K40: T6 REPLACE, T7 AVG | L40: Yes – CEIL(AVG(Salary) - AVG(REPLACE(Salary, '0', ''))) | M40: Added (verified) | N40: =IF(M40="Added (verified)","Yes","No") -> Yes | O40: H9 | P40: Engines: MySQL, MS SQL Server, Oracle, DB2.
...

Sheet Validation Report
A1: SQL Question Bank – Validation Report
A2: Checked on 3–4 Oct 2026 against each platform's live problem data. The learning sequence is the row order of 'SQL Practice Links' (Topic 1 = SELECT & Column Aliases ... Topic 26 = Stored Functions & Procedures). Every listed problem is free, appears only once, and needs only its own topic and earlier ones.
A4: Summary
B5: Topics covered | D5: =COUNTA('SQL Practice Links'!C2:C27) -> 26 | E5: Grouped into 7 sections, from SQL basics to advanced SQL.
B6: Problem slots (topics x 5) | D6: =COUNTA('Question Bank Details'!$A$2:$A$131) -> 130 | E6: Five problems per topic, ordered Q1 (easiest) to Q5 (hardest).
B7: Problems added (verified) | D7: =COUNTIF('Question Bank Details'!$M$2:$M$131,"Added (verified)") -> 125 | E7: Each one opened live: exists, free, title and difficulty confirmed.
B8: Slots with no suitable free problem | D8: =COUNTIF('Question Bank Details'!$M$2:$M$131,"Not available") -> 5 | E8: Grey cells in 'SQL Practice Links'; reasons are listed below.
B9: Topics with all 5 problems | D9: =COUNTIF($D$24:$D$49,5) -> 24
B10: Topics short of 5 | D10: =COUNTIF($D$24:$D$49,"<5") -> 2 | E10: Recursive CTEs (4) and Stored Functions & Procedures (1).
B11: Duplicate problem links | D11: =SUMPRODUCT(('Question Bank Details'!$H$2:$H$131<>"-")*(COUNTIF('Question Bank Details'!$H$2:$H$131,'Question Bank Details'!$H$2:$H$131)>1)) -> 0 | E11: Each problem is used in exactly one topic.
B12: Links that could not be verified as free | D12: =COUNTIF('Question Bank Details'!$I$2:$I$131,"Not verifiable*") -> 0
B14: Problems by platform
B15: LeetCode | D15: =COUNTIF('Question Bank Details'!$F$2:$F$131,"LeetCode") -> 52 | E15: Free Database problems only (Premium excluded).
B16: HackerRank | D16: =COUNTIF('Question Bank Details'!$F$2:$F$131,"HackerRank") -> 29 | E16: SQL domain challenges (all free).
B17: CodeChef | D17: =COUNTIF('Question Bank Details'!$F$2:$F$131,"CodeChef") -> 44 | E17: Free, non-Pro lessons of 'Learn SQL', 'Learn Advanced SQL' and 'SQL Practice Queries'.
B18: Codeforces | D18: =COUNTIF('Question Bank Details'!$F$2:$F$131,"Codeforces") -> 0 | E18: No SQL problems exist on Codeforces (its problem set has no database / SQL tasks).
B19: GeeksforGeeks | D19: =COUNTIF('Question Bank Details'!$F$2:$F$131,"GeeksforGeeks") -> 0 | E19: No SQL problems on GfG Practice: a full catalogue scan found none that accept SQL (the database-style ones accept only Python / pandas).
A22: Per-topic status
A23: # | B23: Section | C23: Topic | D23: Problems | E23: Not available | F23: Gap to 5 | G23: LeetCode | H23: HackerRank | I23: CodeChef | J23: Other verified free options (not counted)
A24: 1 | B24: SQL Basics | C24: SELECT & Column Aliases | D24: =COUNTIFS('Question Bank Details'!$A$2:$A$131,$A24,'Question Bank Details'!$N$2:$N$131,"Yes") -> 5 | E24: =COUNTIFS('Question Bank Details'!$A$2:$A$131,$A24,'Question Bank Details'!$M$2:$M$131,"Not available") -> 0 | F24: =MAX(0,5-D24) -> 0 | G24: =COUNTIFS('Question Bank Details'!$A$2:$A$131,$A24,'Question Bank Details'!$F$2:$F$131,"LeetCode") -> 0 | H24: =COUNTIFS('Question Bank Details'!$A$2:$A$131,$A24,'Question Bank Details'!$F$2:$F$131,"HackerRank") -> 2 | I24: =COUNTIFS('Question Bank Details'!$A$2:$A$131,$A24,'Question Bank Details'!$F$2:$F$131,"CodeChef") -> 3
